docker logs celery_beat
celery beat v5.4.0 (opalescent) is starting.
__    -    ... __   -        _
LocalTime -> 2024-12-23 11:15:52
Configuration ->
    . broker -> redis://redis:6379/0
    . loader -> celery.loaders.app.AppLoader
    . scheduler -> celery.beat.PersistentScheduler
    . db -> celerybeat-schedule
    . logfile -> [stderr]@%INFO
    . maxinterval -> 5.00 minutes (300s)
[2024-12-23 11:15:52,817: INFO/MainProcess] beat: Starting...
[2024-12-23 11:17:53,223: INFO/MainProcess] Scheduler: Sending due task check-inactive-users (users.tasks.check_inactive_users)
[2024-12-23 11:19:53,062: INFO/MainProcess] Scheduler: Sending due task check-inactive-users (users.tasks.check_inactive_users)
[2024-12-23 11:21:53,063: INFO/MainProcess] Scheduler: Sending due task check-inactive-users (users.tasks.check_inactive_users)
[2024-12-23 11:23:53,062: INFO/MainProcess] Scheduler: Sending due task check-inactive-users (users.tasks.check_inactive_users)


 
docker logs celery_worker     
/usr/local/lib/python3.10/site-packages/celery/platforms.py:829: SecurityWarning: You're running the worker with superuser privileges: this is
absolutely not recommended!

Please specify a different user using the --uid option.

User information: uid=0 euid=0 gid=0 egid=0

  warnings.warn(SecurityWarning(ROOT_DISCOURAGED.format(
 
 -------------- celery@ca087972fc76 v5.4.0 (opalescent)
--- ***** ----- 
-- ******* ---- Linux-5.15.49-linuxkit-x86_64-with-glibc2.36 2024-12-23 11:15:52
- *** --- * --- 
- ** ---------- [config]
- ** ---------- .> app:         myproject:0x7f246f4aa500
- ** ---------- .> transport:   redis://redis:6379/0
- ** ---------- .> results:     redis://redis:6379/0
- *** --- * --- .> concurrency: 6 (prefork)
-- ******* ---- .> task events: OFF (enable -E to monitor tasks in this worker)
--- ***** ----- 
 -------------- [queues]
                .> celery           exchange=celery(direct) key=celery
                

[tasks]
  . myapp.tasks.check_inactive_users

[2024-12-23 11:15:54,058: WARNING/MainProcess] /usr/local/lib/python3.10/site-packages/celery/worker/consumer/consumer.py:508: CPendingDeprecationWarning: The broker_connection_retry configuration setting will no longer determine
whether broker connection retries are made during startup in Celery 6.0 and above.
If you wish to retain the existing behavior for retrying connections on startup,
you should set broker_connection_retry_on_startup to True.
  warnings.warn(

[2024-12-23 11:15:54,091: INFO/MainProcess] Connected to redis://redis:6379/0
[2024-12-23 11:15:54,093: WARNING/MainProcess] /usr/local/lib/python3.10/site-packages/celery/worker/consumer/consumer.py:508: CPendingDeprecationWarning: The broker_connection_retry configuration setting will no longer determine
whether broker connection retries are made during startup in Celery 6.0 and above.
If you wish to retain the existing behavior for retrying connections on startup,
you should set broker_connection_retry_on_startup to True.
  warnings.warn(

[2024-12-23 11:15:54,100: INFO/MainProcess] mingle: searching for neighbors
[2024-12-23 11:15:55,145: INFO/MainProcess] mingle: all alone
[2024-12-23 11:15:55,223: INFO/MainProcess] celery@ca087972fc76 ready.
[2024-12-23 11:17:53,377: ERROR/MainProcess] Received unregistered task of type 'users.tasks.check_inactive_users'.
The message has been ignored and discarded.

Did you remember to import the module containing this task?
Or maybe you're using relative imports?

Please see
https://docs.celeryq.dev/en/latest/internals/protocol.html
for more information.

The full contents of the message body was:
b'[[], {}, {"callbacks": null, "errbacks": null, "chain": null, "chord": null}]' (77b)

The full contents of the message headers:
{'lang': 'py', 'task': 'users.tasks.check_inactive_users', 'id': '95bb3a37-6884-456d-8945-4113f7791096', 'shadow': None, 'eta': None, 'expires': None, 'group': None, 'group_index': None, 'retries': 0, 'timelimit': [None, None], 'root_id': '95bb3a37-6884-456d-8945-4113f7791096', 'parent_id': None, 'argsrepr': '()', 'kwargsrepr': '{}', 'origin': 'gen1@bca2abe29c5b', 'ignore_result': False, 'replaced_task_nesting': 0, 'stamped_headers': None, 'stamps': {}}

The delivery info for this task is:
{'exchange': '', 'routing_key': 'celery'}
Traceback (most recent call last):
  File "/usr/local/lib/python3.10/site-packages/celery/worker/consumer/consumer.py", line 659, in on_task_received
    strategy = strategies[type_]
KeyError: 'users.tasks.check_inactive_users'
[2024-12-23 11:19:53,068: ERROR/MainProcess] Received unregistered task of type 'users.tasks.check_inactive_users'.
The message has been ignored and discarded.

Did you remember to import the module containing this task?
Or maybe you're using relative imports?

Please see
https://docs.celeryq.dev/en/latest/internals/protocol.html
for more information.

The full contents of the message body was:
b'[[], {}, {"callbacks": null, "errbacks": null, "chain": null, "chord": null}]' (77b)

The full contents of the message headers:
{'lang': 'py', 'task': 'users.tasks.check_inactive_users', 'id': '74a81031-966f-4721-85d4-ac268863676d', 'shadow': None, 'eta': None, 'expires': None, 'group': None, 'group_index': None, 'retries': 0, 'timelimit': [None, None], 'root_id': '74a81031-966f-4721-85d4-ac268863676d', 'parent_id': None, 'argsrepr': '()', 'kwargsrepr': '{}', 'origin': 'gen1@bca2abe29c5b', 'ignore_result': False, 'replaced_task_nesting': 0, 'stamped_headers': None, 'stamps': {}}

The delivery info for this task is:
{'exchange': '', 'routing_key': 'celery'}
Traceback (most recent call last):
  File "/usr/local/lib/python3.10/site-packages/celery/worker/consumer/consumer.py", line 659, in on_task_received
    strategy = strategies[type_]
KeyError: 'users.tasks.check_inactive_users'
[2024-12-23 11:21:53,068: ERROR/MainProcess] Received unregistered task of type 'users.tasks.check_inactive_users'.
The message has been ignored and discarded.

Did you remember to import the module containing this task?
Or maybe you're using relative imports?

Please see
https://docs.celeryq.dev/en/latest/internals/protocol.html
for more information.

The full contents of the message body was:
b'[[], {}, {"callbacks": null, "errbacks": null, "chain": null, "chord": null}]' (77b)

The full contents of the message headers:
{'lang': 'py', 'task': 'users.tasks.check_inactive_users', 'id': '2f2d0c61-78c5-4c9d-911b-0c5cf63d812f', 'shadow': None, 'eta': None, 'expires': None, 'group': None, 'group_index': None, 'retries': 0, 'timelimit': [None, None], 'root_id': '2f2d0c61-78c5-4c9d-911b-0c5cf63d812f', 'parent_id': None, 'argsrepr': '()', 'kwargsrepr': '{}', 'origin': 'gen1@bca2abe29c5b', 'ignore_result': False, 'replaced_task_nesting': 0, 'stamped_headers': None, 'stamps': {}}

The delivery info for this task is:
{'exchange': '', 'routing_key': 'celery'}
Traceback (most recent call last):
  File "/usr/local/lib/python3.10/site-packages/celery/worker/consumer/consumer.py", line 659, in on_task_received
    strategy = strategies[type_]
KeyError: 'users.tasks.check_inactive_users'